<?xml version="1.0"?>
<robot name="rrr_robot">
  <!-- Base -->
  <link name="base_link">
    <visual>
      <geometry>
        <cylinder radius="0.05" length="0.1"/>
      </geometry>
      <origin xyz="0 0 0" rpy="0 0 0"/>
      <material name="blue"/>
    </visual>
  </link>

<!-- Primer eslabón -->
<link name="link1">
  <visual>
    <geometry>
      <cylinder radius="0.02" length="0.3"/>
    </geometry>
    <origin xyz="0 0 0.15" rpy="0 0 0"/>
    <material name="cyan">
      <color rgba="0 1 1 1"/>
    </material>
  </visual>
</link>

<joint name="joint1" type="fixed">
  <parent link="base_link"/>
  <child link="link1"/>
  <origin xyz="0 0 0.05" rpy="0 0 0"/>
</joint>

<!-- Segundo eslabón -->
<link name="link2">
  <visual>
    <geometry>
      <cylinder radius="0.02" length="0.3"/>
    </geometry>
    <!-- Rotación para que sea perpendicular al eslabón 1 -->
    <origin xyz="0 0.15 0" rpy="1.57 0 0"/>
    <material name="green">
      <color rgba="0 1 0 1"/>
    </material>
  </visual>
</link>

<joint name="joint2" type="revolute">
  <parent link="link1"/>
  <child link="link2"/>
  <origin xyz="0 0 0.3" rpy="0 0 0"/>
  <!-- Eje de rotación perpendicular al primer eje -->
  <axis xyz="0 0 1"/>
  <limit effort="10" velocity="1" lower="-1.57" upper="1.57"/>
</joint>

<!-- Tercer eslabón -->
<link name="link3">
  <visual>
    <geometry>
      <cylinder radius="0.02" length="0.2"/>
    </geometry>
    <!-- Rotación para que sea perpendicular al eslabón 2 -->
    <origin xyz="0.1 0 0" rpy="0 1.57 0"/>
    <material name="red">
      <color rgba="1 0 0 1"/>
    </material>
  </visual>
</link>

<joint name="joint3" type="revolute">
  <parent link="link2"/>
  <child link="link3"/>
  <origin xyz="0 0.3 0" rpy="0 0 0"/>
  <!-- Rotación en eje Z -->
  <axis xyz="0 0 1"/>
  <limit effort="10" velocity="1" lower="-1.2" upper="1.57"/>
</joint>

<!-- Cuarto eslabón -->
<link name="link4">
  <visual>
    <geometry>
      <cylinder radius="0.015" length="0.25"/>
    </geometry>
    <!-- Orientación vertical (eje Z) -->
    <origin xyz="0 0 -0.125" rpy="0 0 0"/>
    <material name="blue">
      <color rgba="0 0 1 1"/>
    </material>
  </visual>
</link>

<joint name="joint4" type="prismatic">
  <parent link="link3"/>
  <child link="link4"/>
  <origin xyz="0.2 0 0" rpy="0 0 0"/>
  <!-- Eje Z para movimiento vertical -->
  <axis xyz="0 0 1"/>
  <limit effort="10" velocity="0.1" lower="0" upper="0.2"/>
</joint>
</robot>
	
